Workbook

Sheet usdjpy
I1: OPEN | J1: AVERAGE RET | K1: =SUBTOTAL(1,G12:G4236) -> -0.0001117501 | L1: AVE POS RET | M1: 0.0039924731 | O1: POS COUNT | P1: 2031 | Q1: =P1/$AC$25 -> 0.48071006 | S1: ADJ POS RET | T1: =M1*Q1 -> 0.001919222 | V1: STD DEV | W1: 1 | X1: 2 | Y1: 3 | AA1: STD DEV2 | AB1: ACTUAL | AC1: ACTUAL% | AD1: NORMAL | AE1: NORMAL%
I2: TO | J2: COUNT | K2: =SUBTOTAL(2,G12:G4236) -> 4225 | L2: AVE NEG RET | M2: -0.0039929535 | O2: NEG COUNT | P2: 2149 | Q2: =P2/$AC$25 -> 0.50863905 | S2: ADJ NEG RET | T2: =M2*Q2 -> -0.0020309721 | V2: UPPER | W2: =AC13+(1*AC17) -> 0.0054905628 | X2: =AC13+(2*AC17) -> 0.011092876 | Y2: =AC13+(3*AC17) -> 0.016695189 | AA2: 1 | AB2: 3251 | AC2: =AB2/$AC$25 -> 0.76946746 | AD2: =AE2*$AC$25 -> 2881.45 | AE2: 0.682
I3: OPEN | O3: 0 COUNTS | P3: =$AC25-P1-P2 -> 45 | Q3: =P3/$AC$25 -> 0.010650888 | V3: LOWER | W3: =AC13-(1*AC17) -> -0.005714063 | X3: =AC13-(2*AC17) -> -0.011316376 | Y3: =AC13-(3*AC17) -> -0.016918689 | AA3: 2 | AB3: 4004 | AC3: =AB3/$AC$25 -> 0.94769231 | AD3: =AE3*$AC$25 -> 4030.65 | AE3: 0.954
AA4: 3 | AB4: 4161 | AC4: =AB4/$AC$25 -> 0.98485207 | AD4: =AE4*$AC$25 -> 4216.55 | AE4: 0.998
A11: Date | B11: Price | C11: Open | D11: High | E11: Low | F11: Change % | G11: OPEN TO OPEN % | H11: HIGH TO LOW % | L11: INTERVALS | M11: Bin | N11: Frequency | W11: TEXT LABELS | X11: PROBABILITIES | Y11: CUMULATIVE PROBABILITIES | AB11: Column1
A12: 40179 | B12: 93 | C12: 93.01 | D12: 93.05 | E12: 92.98 | F12: 0.0011 | G12: =(C12-C13)/C13 -> 0.0023709451 | H12: =(D12-E12)/E12 -> 0.00075285008 | L12: -0.03 | M12: -0.03 | N12: 3 | W12: =TEXT(M12,"0.00%")&" TO "&TEXT(M13,"0.00%") -> -3.00% TO -2.70% | X12: =N12/$AC$25 -> 0.00071005917 | Y12: =X12 -> 0.00071005917
A13: 40182 | B13: 92.55 | C13: 92.79 | D13: 93.14 | E13: 92.19 | F13: -0.0048 | G13: =(C13-C14)/C14 -> 0.007273122 | H13: =(D13-E13)/E13 -> 0.010304805 | L13: -0.027 | M13: -0.027 | N13: 1 | W13: =TEXT(M13,"0.00%")&" TO "&TEXT(M14,"0.00%") -> -2.70% TO -2.40% | X13: =N13/$AC$25 -> 0.00023668639 | Y13: =X13+Y12 -> 0.00094674556 | AB13: Mean | AC13: -0.0001117501
A14: 40183 | B14: 91.72 | C14: 92.12 | D14: 92.52 | E14: 91.25 | F14: -0.009 | G14: =(C14-C15)/C15 -> 0.0010867203 | H14: =(D14-E14)/E14 -> 0.013917808 | L14: -0.024 | M14: -0.024 | N14: 1 | W14: =TEXT(M14,"0.00%")&" TO "&TEXT(M15,"0.00%") -> -2.40% TO -2.10% | X14: =N14/$AC$25 -> 0.00023668639 | Y14: =X14+Y13 -> 0.001183432 | AB14: Standard Error | AC14: 8.6189429e-05
A15: 40184 | B15: 92.34 | C15: 92.02 | D15: 92.7 | E15: 91.52 | F15: 0.0068 | G15: =(C15-C16)/C16 -> -0.0089391492 | H15: =(D15-E15)/E15 -> 0.012893357 | L15: -0.021 | M15: -0.021 | N15: 2 | W15: =TEXT(M15,"0.00%")&" TO "&TEXT(M16,"0.00%") -> -2.10% TO -1.80% | X15: =N15/$AC$25 -> 0.00047337278 | Y15: =X15+Y14 -> 0.0016568047 | AB15: Median | AC15: -0.00011859583
A16: 40185 | B16: 93.31 | C16: 92.85 | D16: 93.5 | E16: 92.1 | F16: 0.0105 | G16: =(C16-C17)/C17 -> -0.0012907389 | H16: =(D16-E16)/E16 -> 0.015200869 | L16: -0.018 | M16: -0.018 | N16: 10 | W16: =TEXT(M16,"0.00%")&" TO "&TEXT(M17,"0.00%") -> -1.80% TO -1.50% | X16: =N16/$AC$25 -> 0.0023668639 | Y16: =X16+Y15 -> 0.0040236686 | AB16: Mode | AC16: 0
A17: 40186 | B17: 92.61 | C17: 92.97 | D17: 93.61 | E17: 92.29 | F17: -0.0075 | G17: =(C17-C18)/C18 -> 0.0071498213 | H17: =(D17-E17)/E17 -> 0.014302741 | L17: -0.015 | M17: -0.015 | N17: 28 | W17: =TEXT(M17,"0.00%")&" TO "&TEXT(M18,"0.00%") -> -1.50% TO -1.20% | X17: =N17/$AC$25 -> 0.0066272189 | Y17: =X17+Y16 -> 0.010650888 | AB17: Standard Deviation | AC17: 0.0056023129
A18: 40189 | B18: 92.08 | C18: 92.31 | D18: 92.59 | E18: 91.81 | F18: -0.0057 | G18: =(C18-C19)/C19 -> 0.0081913499 | H18: =(D18-E18)/E18 -> 0.0084958066 | L18: -0.012 | M18: -0.012 | N18: 43 | W18: =TEXT(M18,"0.00%")&" TO "&TEXT(M19,"0.00%") -> -1.20% TO -0.90% | X18: =N18/$AC$25 -> 0.010177515 | Y18: =X18+Y17 -> 0.020828402 | AB18: Sample Variance | AC18: 3.138591e-05
A19: 40190 | B19: 90.95 | C19: 91.56 | D19: 92.35 | E19: 90.74 | F19: -0.0123 | G19: =(C19-C20)/C20 -> 0.0039473684 | H19: =(D19-E19)/E19 -> 0.017743002 | L19: -0.009 | M19: -0.009 | N19: 112 | W19: =TEXT(M19,"0.00%")&" TO "&TEXT(M20,"0.00%") -> -0.90% TO -0.60% | X19: =N19/$AC$25 -> 0.026508876 | Y19: =X19+Y18 -> 0.047337278 | AB19: Kurtosis | AC19: 4.796437
A20: 40191 | B20: 91.4 | C20: 91.2 | D20: 91.52 | E20: 90.9 | F20: 0.0049 | G20: =(C20-C21)/C21 -> -0.0010952903 | H20: =(D20-E20)/E20 -> 0.0068206821 | L20: -0.006 | M20: -0.006 | N20: 259 | W20: =TEXT(M20,"0.00%")&" TO "&TEXT(M21,"0.00%") -> -0.60% TO -0.30% | X20: =N20/$AC$25 -> 0.061301775 | Y20: =X20+Y19 -> 0.10863905 | AB20: Skewness | AC20: 0.34116143
A21: 40192 | B21: 91.14 | C21: 91.3 | D21: 92.01 | E21: 90.84 | F21: -0.0028 | G21: =(C21-C22)/C22 -> 0.003076247 | H21: =(D21-E21)/E21 -> 0.012879789 | L21: -0.003 | M21: -0.003 | N21: 612 | W21: =TEXT(M21,"0.00%")&" TO "&TEXT(M22,"0.00%") -> -0.30% TO 0.00% | X21: =N21/$AC$25 -> 0.14485207 | Y21: =X21+Y20 -> 0.25349112 | AB21: Range | AC21: 0.073916793
A22: 40193 | B22: 90.78 | C22: 91.02 | D22: 91.31 | E22: 90.59 | F22: -0.0039 | G22: =(C22-C23)/C23 -> 0.0026437541 | H22: =(D22-E22)/E22 -> 0.0079478971 | L22: 0 | M22: 0 | N22: 1123 | W22: =TEXT(M22,"0.00%")&" TO "&TEXT(M23,"0.00%") -> 0.00% TO 0.30% | X22: =N22/$AC$25 -> 0.26579882 | Y22: =X22+Y21 -> 0.51928994 | AB22: Minimum | AC22: -0.034253685
A23: 40196 | B23: 90.72 | C23: 90.78 | D23: 91.06 | E23: 90.62 | F23: -0.0007 | G23: =(C23-C24)/C24 -> -0.0019788918 | H23: =(D23-E23)/E23 -> 0.0048554403 | L23: 0.003 | M23: 0.003 | N23: 1061 | W23: =TEXT(M23,"0.00%")&" TO "&TEXT(M24,"0.00%") -> 0.30% TO 0.60% | X23: =N23/$AC$25 -> 0.25112426 | Y23: =X23+Y22 -> 0.7704142 | AB23: Maximum | AC23: 0.039663108
A24: 40197 | B24: 91.1 | C24: 90.96 | D24: 91.24 | E24: 90.31 | F24: 0.0042 | G24: =(C24-C25)/C25 -> -0.0025222064 | H24: =(D24-E24)/E24 -> 0.010297863 | L24: 0.006 | M24: 0.006 | N24: 546 | W24: =TEXT(M24,"0.00%")&" TO "&TEXT(M25,"0.00%") -> 0.60% TO 0.90% | X24: =N24/$AC$25 -> 0.12923077 | Y24: =X24+Y23 -> 0.89964497 | AB24: Sum | AC24: -0.47214419
A25: 40198 | B25: 91.25 | C25: 91.19 | D25: 91.4 | E25: 90.79 | F25: 0.0016 | G25: =(C25-C26)/C26 -> 0.0037424326 | H25: =(D25-E25)/E25 -> 0.0067188016 | L25: 0.009 | M25: 0.009 | N25: 234 | W25: =TEXT(M25,"0.00%")&" TO "&TEXT(M26,"0.00%") -> 0.90% TO 1.20% | X25: =N25/$AC$25 -> 0.055384615 | Y25: =X25+Y24 -> 0.95502959 | AB25: Count | AC25: 4225
A26: 40199 | B26: 90.42 | C26: 90.85 | D26: 91.83 | E26: 90.11 | F26: -0.0091 | G26: =(C26-C27)/C27 -> 0.0076530612 | H26: =(D26-E26)/E26 -> 0.019087782 | L26: 0.012 | M26: 0.012 | N26: 97 | W26: =TEXT(M26,"0.00%")&" TO "&TEXT(M27,"0.00%") -> 1.20% TO 1.50% | X26: =N26/$AC$25 -> 0.02295858 | Y26: =X26+Y25 -> 0.97798817
A27: 40200 | B27: 89.89 | C27: 90.16 | D27: 90.52 | E27: 89.78 | F27: -0.0059 | G27: =(C27-C28)/C28 -> -0.0015503876 | H27: =(D27-E27)/E27 -> 0.0082423702 | L27: 0.015 | M27: 0.015 | N27: 45 | W27: =TEXT(M27,"0.00%")&" TO "&TEXT(M28,"0.00%") -> 1.50% TO 1.80% | X27: =N27/$AC$25 -> 0.010650888 | Y27: =X27+Y26 -> 0.98863905
A28: 40203 | B28: 90.23 | C28: 90.3 | D28: 90.32 | E28: 89.81 | F28: 0.0038 | G28: =(C28-C29)/C29 -> 0.0038910506 | H28: =(D28-E28)/E28 -> 0.0056786549 | L28: 0.018 | M28: 0.018 | N28: 19 | W28: =TEXT(M28,"0.00%")&" TO "&TEXT(M29,"0.00%") -> 1.80% TO 2.10% | X28: =N28/$AC$25 -> 0.0044970414 | Y28: =X28+Y27 -> 0.99313609
A29: 40204 | B29: 89.62 | C29: 89.95 | D29: 90.52 | E29: 89.34 | F29: -0.0068 | G29: =(C29-C30)/C30 -> 0.0013358566 | H29: =(D29-E29)/E29 -> 0.01320797 | L29: 0.021 | M29: 0.021 | N29: 9 | W29: =TEXT(M29,"0.00%")&" TO "&TEXT(M30,"0.00%") -> 2.10% TO 2.40% | X29: =N29/$AC$25 -> 0.0021301775 | Y29: =X29+Y28 -> 0.99526627
A30: 40205 | B30: 90 | C30: 89.83 | D30: 90.06 | E30: 89.13 | F30: 0.0042 | G30: =(C30-C31)/C31 -> -0.001111976 | H30: =(D30-E30)/E30 -> 0.010434197 | L30: 0.024 | M30: 0.024 | N30: 10 | W30: =TEXT(M30,"0.00%")&" TO "&TEXT(M31,"0.00%") -> 2.40% TO 2.70% | X30: =N30/$AC$25 -> 0.0023668639 | Y30: =X30+Y29 -> 0.99763314
A31: 40206 | B31: 89.88 | C31: 89.93 | D31: 90.51 | E31: 89.63 | F31: -0.0013 | G31: =(C31-C32)/C32 -> -0.0017760018 | H31: =(D31-E31)/E31 -> 0.0098181412 | L31: 0.027 | M31: 0.027 | N31: 3 | W31: =TEXT(M31,"0.00%")&" TO "&TEXT(M32,"0.00%") -> 2.70% TO 3.00% | X31: =N31/$AC$25 -> 0.00071005917 | Y31: =X31+Y30 -> 0.9983432
A32: 40207 | B32: 90.3 | C32: 90.09 | D32: 90.9 | E32: 89.58 | F32: 0.0047 | G32: =(C32-C33)/C33 -> -0.0014409222 | H32: =(D32-E32)/E32 -> 0.014735432 | L32: 0.03 | M32: 0.03 | N32: 2 | W32: =TEXT(M32,"0.00%")&" TO "&TEXT(M33,"0.00%") -> 3.00% TO More | X32: =N32/$AC$25 -> 0.00047337278 | Y32: =X32+Y31 -> 0.99881657
A33: 40210 | B33: 90.62 | C33: 90.22 | D33: 90.89 | E33: 89.79 | F33: 0.0035 | G33: =(C33-C34)/C34 -> -0.0029837551 | H33: =(D33-E33)/E33 -> 0.012250807 | M33: More | N33: 5 | X33: =N33/$AC$25 -> 0.001183432 | Y33: =X33+Y32 -> 1
A34: 40211 | B34: 90.38 | C34: 90.49 | D34: 90.9 | E34: 90.26 | F34: -0.0026 | G34: =(C34-C35)/C35 -> -0.0020952801 | H34: =(D34-E34)/E34 -> 0.0070906271
A35: 40212 | B35: 90.97 | C35: 90.68 | D35: 91.22 | E35: 90.08 | F35: 0.0065 | G35: =(C35-C36)/C36 -> 0.0073317041 | H35: =(D35-E35)/E35 -> 0.012655417
A36: 40213 | B36: 88.95 | C36: 90.02 | D36: 91.06 | E36: 88.56 | F36: -0.0222 | G36: =(C36-C37)/C37 -> 0.0098721113 | H36: =(D36-E36)/E36 -> 0.028229449
A37: 40214 | B37: 89.33 | C37: 89.14 | D37: 89.8 | E37: 88.82 | F37: 0.0043 | G37: =(C37-C38)/C38 -> -0.0027967334 | H37: =(D37-E37)/E37 -> 0.011033551
A38: 40217 | B38: 89.3 | C38: 89.39 | D38: 89.55 | E38: 89.14 | F38: -0.0003 | G38: =(C38-C39)/C39 -> -0.0013406323 | H38: =(D38-E38)/E38 -> 0.0045995064 | L38: INTERVALS | M38: Bin | N38: Frequency | X38: PROBABILITIES | Y38: CUMULATIVE PROBABILITIES | AB38: Column1
A39: 40218 | B39: 89.65 | C39: 89.51 | D39: 89.81 | E39: 89.15 | F39: 0.0039 | G39: =(C39-C40)/C40 -> -0.0032293987 | H39: =(D39-E39)/E39 -> 0.0074032529 | L39: 0.002 | M39: 0.002 | N39: 32 | X39: =N39/$AC$52 -> 0.0075739645 | Y39: =X39 -> 0.0075739645
A40: 40219 | B40: 89.97 | C40: 89.8 | D40: 90.05 | E40: 89.23 | F40: 0.0036 | G40: =(C40-C41)/C41 -> -0.00044523598 | H40: =(D40-E40)/E40 -> 0.0091897344 | L40: 0.004 | M40: 0.004 | N40: 487 | X40: =N40/$AC$52 -> 0.11526627 | Y40: =X40+Y39 -> 0.12284024 | AB40: Mean | AC40: 0.0084372433
A41: 40220 | B41: 89.72 | C41: 89.84 | D41: 90.12 | E41: 89.56 | F41: -0.0028 | G41: =(C41-C42)/C42 -> -0.00033381551 | H41: =(D41-E41)/E41 -> 0.0062527914 | L41: 0.006 | M41: 0.006 | N41: 957 | X41: =N41/$AC$52 -> 0.22650888 | Y41: =X41+Y40 -> 0.34934911 | AB41: Standard Error | AC41: 8.0850789e-05
A42: 40221 | B42: 90.02 | C42: 89.87 | D42: 90.35 | E42: 89.58 | F42: 0.0033 | G42: =(C42-C43)/C43 -> -0.0023312611 | H42: =(D42-E42)/E42 -> 0.0085956687 | L42: 0.008 | M42: 0.008 | N42: 943 | X42: =N42/$AC$52 -> 0.22319527 | Y42: =X42+Y41 -> 0.57254438 | AB42: Median | AC42: 0.007310504
A43: 40224 | B43: 89.98 | C43: 90.08 | D43: 90.21 | E43: 89.9 | F43: -0.0004 | G43: =(C43-C44)/C44 -> 0 | H43: =(D43-E43)/E43 -> 0.0034482759 | L43: 0.01 | M43: 0.01 | N43: 685 | X43: =N43/$AC$52 -> 0.16213018 | Y43: =X43+Y42 -> 0.73467456 | AB43: Mode | AC43: 0.0050907192
A44: 40225 | B44: 90.1 | C44: 90.08 | D44: 90.49 | E44: 89.71 | F44: 0.0013 | G44: =(C44-C45)/C45 -> -0.0068357222 | H44: =(D44-E44)/E44 -> 0.0086946829 | L44: 0.012 | M44: 0.012 | N44: 439 | X44: =N44/$AC$52 -> 0.10390533 | Y44: =X44+Y43 -> 0.83857988 | AB44: Standard Deviation | AC44: 0.0052553013
A45: 40226 | B45: 91.36 | C45: 90.7 | D45: 91.38 | E45: 90.11 | F45: 0.014 | G45: =(C45-C46)/C46 -> -0.0089597902 | H45: =(D45-E45)/E45 -> 0.014093885 | L45: 0.014 | M45: 0.014 | N45: 249 | X45: =N45/$AC$52 -> 0.058934911 | Y45: =X45+Y44 -> 0.89751479 | AB45: Sample Variance | AC45: 2.7618191e-05
A46: 40227 | B46: 91.22 | C46: 91.52 | D46: 91.76 | E46: 90.57 | F46: -0.0015 | G46: =(C46-C47)/C47 -> -0.0013094718 | H46: =(D46-E46)/E46 -> 0.013139009 | L46: 0.016 | M46: 0.016 | N46: 159 | X46: =N46/$AC$52 -> 0.037633136 | Y46: =X46+Y45 -> 0.93514793 | AB46: Kurtosis | AC46: 21.993409
...

Sheet usdcad
I1: open to open | J1: average returns | K1: =SUBTOTAL(1,G12:G4236) -> -5.039277e-05 | M1: avg pos | N1: 0.0035499287 | P1: pos count | Q1: 2038 | R1: =Q1/$T$25 -> 0.48236686 | T1: adj post ret | U1: =N1*R1 -> 0.001712368 | W1: std dev | X1: 1 | Y1: 2 | Z1: 3 | AB1: std dev 2 | AC1: actual | AD1: actual % | AE1: normal | AF1: normal%
J2: counts | K2: =SUBTOTAL(2,G12:G4236) -> 4225 | M2: avg neg | N2: -0.0034769674 | P2: neg count | Q2: 2142 | R2: =Q2/$T$25 -> 0.50698225 | T2: adj neg ret | U2: =N2*R2 -> -0.0017627607 | W2: upper | X2: =T13+(1*T17) -> 0.0046270213 | Y2: =T13+(2*T17) -> 0.0093044354 | Z2: =T13+(3*T17) -> 0.013981849 | AB2: 1 | AC2: 3091 | AD2: =AC2/$T$25 -> 0.73159763 | AE2: =AF2*$T$25 -> 2881.45 | AF2: 0.682
P3: 0 count | Q3: =T25-Q1-Q2 -> 45 | R3: =Q3/$T$25 -> 0.010650888 | W3: lower | X3: =T13-(1*T17) -> -0.0047278068 | Y3: =T13-(2*T17) -> -0.0094052209 | Z3: =T13-(3*T17) -> -0.014082635 | AB3: 2 | AC3: 4000 | AD3: =AC3/$T$25 -> 0.94674556 | AE3: =AF3*$T$25 -> 4030.65 | AF3: 0.954
AB4: 3 | AC4: 4179 | AD4: =AC4/$T$25 -> 0.98911243 | AE4: =AF4*$T$25 -> 4216.55 | AF4: 0.998
A11: Date | B11: Price | C11: Open | D11: High | E11: Low | F11: Change % | G11: open to open | H11: high to low | L11: intervals | M11: Bin | N11: Frequency | O11: text labels | P11: PROBABILITIES | Q11: CUMMULATIV PROBABILITIES | S11: Column1
A12: 40179 | B12: 1.0517 | C12: 1.0527 | D12: 1.054 | E12: 1.052 | F12: -0.0001 | G12: =(C12-C13)/C13 -> 0.00085567598 | H12: =(D12-E12)/E12 -> 0.0019011407 | L12: -0.03 | M12: -0.03 | N12: 0 | O12: =TEXT(L12,"0.00%")&" TO "&TEXT(L13,"0.00%") -> -3.00% TO -2.70% | P12: =N12/$T$25 -> 0 | Q12: =P12 -> 0
A13: 40182 | B13: 1.0414 | C13: 1.0518 | D13: 1.0521 | E13: 1.0352 | F13: -0.0098 | G13: =(C13-C14)/C14 -> 0.0097926267 | H13: =(D13-E13)/E13 -> 0.016325348 | L13: -0.027 | M13: -0.027 | N13: 0 | O13: =TEXT(L13,"0.00%")&" TO "&TEXT(L14,"0.00%") -> -2.70% TO -2.40% | P13: =N13/$T$25 -> 0 | Q13: =P13+Q12 -> 0 | S13: Mean | T13: -5.039277e-05
A14: 40183 | B14: 1.0394 | C14: 1.0416 | D14: 1.0427 | E14: 1.0336 | F14: -0.0019 | G14: =(C14-C15)/C15 -> 0.0026954178 | H14: =(D14-E14)/E14 -> 0.0088041796 | L14: -0.024 | M14: -0.024 | N14: 1 | O14: =TEXT(L14,"0.00%")&" TO "&TEXT(L15,"0.00%") -> -2.40% TO -2.10% | P14: =N14/$T$25 -> 0.00023668639 | Q14: =P14+Q13 -> 0.00023668639 | S14: Standard Error | T14: 7.1960216e-05
A15: 40184 | B15: 1.0316 | C15: 1.0388 | D15: 1.0411 | E15: 1.0312 | F15: -0.0075 | G15: =(C15-C16)/C16 -> 0.0062966192 | H15: =(D15-E15)/E15 -> 0.0096004655 | L15: -0.021 | M15: -0.021 | N15: 0 | O15: =TEXT(L15,"0.00%")&" TO "&TEXT(L16,"0.00%") -> -2.10% TO -1.80% | P15: =N15/$T$25 -> 0 | Q15: =P15+Q14 -> 0.00023668639 | S15: Median | T15: -0.00010064412
A16: 40185 | B16: 1.0345 | C16: 1.0323 | D16: 1.0376 | E16: 1.0291 | F16: 0.0028 | G16: =(C16-C17)/C17 -> -0.0021266312 | H16: =(D16-E16)/E16 -> 0.0082596443 | L16: -0.018 | M16: -0.018 | N16: 8 | O16: =TEXT(L16,"0.00%")&" TO "&TEXT(L17,"0.00%") -> -1.80% TO -1.50% | P16: =N16/$T$25 -> 0.0018934911 | Q16: =P16+Q15 -> 0.0021301775 | S16: Mode | T16: 0
A17: 40186 | B17: 1.03 | C17: 1.0345 | D17: 1.0387 | E17: 1.0295 | F17: -0.0043 | G17: =(C17-C18)/C18 -> 0.0054427058 | H17: =(D17-E17)/E17 -> 0.0089363769 | L17: -0.015 | M17: -0.015 | N17: 11 | O17: =TEXT(L17,"0.00%")&" TO "&TEXT(L18,"0.00%") -> -1.50% TO -1.20% | P17: =N17/$T$25 -> 0.0026035503 | Q17: =P17+Q16 -> 0.0047337278 | S17: Standard Deviation | T17: 0.0046774141
A18: 40189 | B18: 1.0333 | C18: 1.0289 | D18: 1.0345 | E18: 1.0252 | F18: 0.0032 | G18: =(C18-C19)/C19 -> -0.004450895 | H18: =(D18-E18)/E18 -> 0.0090714007 | L18: -0.012 | M18: -0.012 | N18: 31 | O18: =TEXT(L18,"0.00%")&" TO "&TEXT(L19,"0.00%") -> -1.20% TO -0.90% | P18: =N18/$T$25 -> 0.0073372781 | Q18: =P18+Q17 -> 0.012071006 | S18: Sample Variance | T18: 2.1878202e-05
A19: 40190 | B19: 1.0393 | C19: 1.0335 | D19: 1.0416 | E19: 1.0313 | F19: 0.0058 | G19: =(C19-C20)/C20 -> -0.0055806793 | H19: =(D19-E19)/E19 -> 0.0099873946 | L19: -0.009 | M19: -0.009 | N19: 84 | O19: =TEXT(L19,"0.00%")&" TO "&TEXT(L20,"0.00%") -> -0.90% TO -0.60% | P19: =N19/$T$25 -> 0.019881657 | Q19: =P19+Q18 -> 0.031952663 | S19: Kurtosis | T19: 1.7960739
A20: 40191 | B20: 1.0307 | C20: 1.0393 | D20: 1.0413 | E20: 1.0288 | F20: -0.0083 | G20: =(C20-C21)/C21 -> 0.0084416845 | H20: =(D20-E20)/E20 -> 0.012150078 | L20: -0.006 | M20: -0.006 | N20: 231 | O20: =TEXT(L20,"0.00%")&" TO "&TEXT(L21,"0.00%") -> -0.60% TO -0.30% | P20: =N20/$T$25 -> 0.054674556 | Q20: =P20+Q19 -> 0.086627219 | S20: Skewness | T20: -0.054932439
A21: 40192 | B21: 1.0232 | C21: 1.0306 | D21: 1.0324 | E21: 1.0224 | F21: -0.0073 | G21: =(C21-C22)/C22 -> 0.0071337829 | H21: =(D21-E21)/E21 -> 0.0097809077 | L21: -0.003 | M21: -0.003 | N21: 596 | O21: =TEXT(L21,"0.00%")&" TO "&TEXT(L22,"0.00%") -> -0.30% TO 0.00% | P21: =N21/$T$25 -> 0.14106509 | Q21: =P21+Q20 -> 0.22769231 | S21: Range | T21: 0.0475149
A22: 40193 | B22: 1.0287 | C22: 1.0233 | D22: 1.0316 | E22: 1.0231 | F22: 0.0054 | G22: =(C22-C23)/C23 -> -0.0067941376 | H22: =(D22-E22)/E22 -> 0.0083080833 | L22: 0 | M22: 0 | N22: 1225 | O22: =TEXT(L22,"0.00%")&" TO "&TEXT(L23,"0.00%") -> 0.00% TO 0.30% | P22: =N22/$T$25 -> 0.28994083 | Q22: =P22+Q21 -> 0.51763314 | S22: Minimum | T22: -0.026057719
A23: 40196 | B23: 1.0261 | C23: 1.0303 | D23: 1.0316 | E23: 1.0247 | F23: -0.0025 | G23: =(C23-C24)/C24 -> 0.0037996882 | H23: =(D23-E23)/E23 -> 0.0067336781 | L23: 0.003 | M23: 0.003 | N23: 1096 | O23: =TEXT(L23,"0.00%")&" TO "&TEXT(L24,"0.00%") -> 0.30% TO 0.60% | P23: =N23/$T$25 -> 0.25940828 | Q23: =P23+Q22 -> 0.77704142 | S23: Maximum | T23: 0.021457181
A24: 40197 | B24: 1.0305 | C24: 1.0264 | D24: 1.035 | E24: 1.0248 | F24: 0.0043 | G24: =(C24-C25)/C25 -> -0.0043651179 | H24: =(D24-E24)/E24 -> 0.0099531616 | L24: 0.006 | M24: 0.006 | N24: 576 | O24: =TEXT(L24,"0.00%")&" TO "&TEXT(L25,"0.00%") -> 0.60% TO 0.90% | P24: =N24/$T$25 -> 0.13633136 | Q24: =P24+Q23 -> 0.91337278 | S24: Sum | T24: -0.21290945
A25: 40198 | B25: 1.046 | C25: 1.0309 | D25: 1.0491 | E25: 1.0303 | F25: 0.015 | G25: =(C25-C26)/C26 -> -0.015095061 | H25: =(D25-E25)/E25 -> 0.018247112 | L25: 0.009 | M25: 0.009 | N25: 243 | O25: =TEXT(L25,"0.00%")&" TO "&TEXT(L26,"0.00%") -> 0.90% TO 1.20% | P25: =N25/$T$25 -> 0.057514793 | Q25: =P25+Q24 -> 0.97088757 | S25: Count | T25: 4225
A26: 40199 | B26: 1.0519 | C26: 1.0467 | D26: 1.0526 | E26: 1.0438 | F26: 0.0056 | G26: =(C26-C27)/C27 -> -0.0047542075 | H26: =(D26-E26)/E26 -> 0.0084307339 | L26: 0.012 | M26: 0.012 | N26: 79 | O26: =TEXT(L26,"0.00%")&" TO "&TEXT(L27,"0.00%") -> 1.20% TO 1.50% | P26: =N26/$T$25 -> 0.018698225 | Q26: =P26+Q25 -> 0.9895858
A27: 40200 | B27: 1.0575 | C27: 1.0517 | D27: 1.0604 | E27: 1.0463 | F27: 0.0053 | G27: =(C27-C28)/C28 -> -0.0059546314 | H27: =(D27-E27)/E27 -> 0.013476058 | L27: 0.015 | M27: 0.015 | N27: 27 | O27: =TEXT(L27,"0.00%")&" TO "&TEXT(L28,"0.00%") -> 1.50% TO 1.80% | P27: =N27/$T$25 -> 0.0063905325 | Q27: =P27+Q26 -> 0.99597633
A28: 40203 | B28: 1.0581 | C28: 1.058 | D28: 1.0615 | E28: 1.0532 | F28: 0.0006 | G28: =(C28-C29)/C29 -> 0.00018907166 | H28: =(D28-E28)/E28 -> 0.0078807444 | L28: 0.018 | M28: 0.018 | N28: 10 | O28: =TEXT(L28,"0.00%")&" TO "&TEXT(L29,"0.00%") -> 1.80% TO 2.10% | P28: =N28/$T$25 -> 0.0023668639 | Q28: =P28+Q27 -> 0.9983432
A29: 40204 | B29: 1.0623 | C29: 1.0578 | D29: 1.0694 | E29: 1.0545 | F29: 0.004 | G29: =(C29-C30)/C30 -> -0.0046108968 | H29: =(D29-E29)/E29 -> 0.014129919 | L29: 0.021 | M29: 0.021 | N29: 6 | O29: =TEXT(L29,"0.00%")&" TO "&TEXT(L30,"0.00%") -> 2.10% TO 2.40% | P29: =N29/$T$25 -> 0.0014201183 | Q29: =P29+Q28 -> 0.99976331
A30: 40205 | B30: 1.0639 | C30: 1.0627 | D30: 1.069 | E30: 1.0608 | F30: 0.0015 | G30: =(C30-C31)/C31 -> -0.0023469771 | H30: =(D30-E30)/E30 -> 0.0077300151 | L30: 0.024 | M30: 0.024 | N30: 1 | O30: =TEXT(L30,"0.00%")&" TO "&TEXT(L31,"0.00%") -> 2.40% TO 2.70% | P30: =N30/$T$25 -> 0.00023668639 | Q30: =P30+Q29 -> 1
A31: 40206 | B31: 1.0665 | C31: 1.0652 | D31: 1.0669 | E31: 1.0556 | F31: 0.0024 | G31: =(C31-C32)/C32 -> -0.0011252813 | H31: =(D31-E31)/E31 -> 0.010704812 | L31: 0.027 | M31: 0.027 | N31: 0 | O31: =TEXT(L31,"0.00%")&" TO "&TEXT(L32,"0.00%") -> 2.70% TO 3.00% | P31: =N31/$T$25 -> 0
A32: 40207 | B32: 1.0696 | C32: 1.0664 | D32: 1.07 | E32: 1.0623 | F32: 0.0029 | G32: =(C32-C33)/C33 -> -0.0043880123 | H32: =(D32-E32)/E32 -> 0.0072484232 | L32: 0.03 | M32: 0.03 | N32: 0 | P32: =N32/$T$25 -> 0
A33: 40210 | B33: 1.0616 | C33: 1.0711 | D33: 1.0723 | E33: 1.061 | F33: -0.0075 | G33: =(C33-C34)/C34 -> 0.0085687382 | H33: =(D33-E33)/E33 -> 0.01065033 | M33: More | N33: 0 | P33: =N33/$T$25 -> 0
A34: 40211 | B34: 1.0579 | C34: 1.062 | D34: 1.0642 | E34: 1.0564 | F34: -0.0035 | G34: =(C34-C35)/C35 -> 0.003685852 | H34: =(D34-E34)/E34 -> 0.0073835668
A35: 40212 | B35: 1.0621 | C35: 1.0581 | D35: 1.0633 | E35: 1.0545 | F35: 0.004 | G35: =(C35-C36)/C36 -> -0.004328597 | H35: =(D35-E35)/E35 -> 0.0083451873
A36: 40213 | B36: 1.0724 | C36: 1.0627 | D36: 1.0754 | E36: 1.0596 | F36: 0.0097 | G36: =(C36-C37)/C37 -> -0.0099683249 | H36: =(D36-E36)/E36 -> 0.014911287
A37: 40214 | B37: 1.0685 | C37: 1.0734 | D37: 1.0782 | E37: 1.0645 | F37: -0.0036 | G37: =(C37-C38)/C38 -> 0.0046798952 | H37: =(D37-E37)/E37 -> 0.012869892
A38: 40217 | B38: 1.0753 | C38: 1.0684 | D38: 1.0755 | E38: 1.0656 | F38: 0.0064 | G38: =(C38-C39)/C39 -> -0.0060470741 | H38: =(D38-E38)/E38 -> 0.0092905405 | L38: INTERVALS | M38: Bin | N38: Frequency | P38: PROBABILITIES | Q38: CUMMULATIVE PROBABILITIES | S38: Column1
A39: 40218 | B39: 1.0674 | C39: 1.0749 | D39: 1.0777 | E39: 1.0645 | F39: -0.0073 | G39: =(C39-C40)/C40 -> 0.007120772 | H39: =(D39-E39)/E39 -> 0.012400188 | L39: 0.002 | M39: 0.002 | N39: 23 | P39: =N39/$T$52 -> 0.0054424988 | Q39: =P39 -> 0.0054424988
A40: 40219 | B40: 1.0628 | C40: 1.0673 | D40: 1.0709 | E40: 1.0597 | F40: -0.0043 | G40: =(C40-C41)/C41 -> 0.0040451552 | H40: =(D40-E40)/E40 -> 0.010569029 | L40: 0.004 | M40: 0.004 | N40: 574 | P40: =N40/$T$52 -> 0.13582584 | Q40: =P40+Q39 -> 0.14126834 | S40: Mean | T40: 0.0073562846
A41: 40220 | B41: 1.0506 | C41: 1.063 | D41: 1.0635 | E41: 1.048 | F41: -0.0115 | G41: =(C41-C42)/C42 -> 0.011417697 | H41: =(D41-E41)/E41 -> 0.014790076 | L41: 0.006 | M41: 0.006 | N41: 1195 | P41: =N41/$T$52 -> 0.28277331 | Q41: =P41+Q40 -> 0.42404165 | S41: Standard Error | T41: 5.6571582e-05
A42: 40221 | B42: 1.051 | C42: 1.051 | D42: 1.0581 | E42: 1.0488 | F42: 0.0004 | G42: =(C42-C43)/C43 -> -0.00038044512 | H42: =(D42-E42)/E42 -> 0.0088672769 | L42: 0.008 | M42: 0.008 | N42: 977 | P42: =N42/$T$52 -> 0.23118788 | Q42: =P42+Q41 -> 0.65522953 | S42: Median | T42: 0.0065489047
A43: 40224 | B43: 1.0488 | C43: 1.0514 | D43: 1.0535 | E43: 1.0463 | F43: -0.0021 | G43: =(C43-C44)/C44 -> 0.0020968357 | H43: =(D43-E43)/E43 -> 0.0068813916 | L43: 0.01 | M43: 0.01 | N43: 689 | P43: =N43/$T$52 -> 0.16303833 | Q43: =P43+Q42 -> 0.81826787 | S43: Mode | T43: 0.0084307339
A44: 40225 | B44: 1.044 | C44: 1.0492 | D44: 1.0501 | E44: 1.0409 | F44: -0.0046 | G44: =(C44-C45)/C45 -> 0.0052697135 | H44: =(D44-E44)/E44 -> 0.0088385051 | L44: 0.012 | M44: 0.012 | N44: 355 | P44: =N44/$T$52 -> 0.084003786 | Q44: =P44+Q43 -> 0.90227165 | S44: Standard Deviation | T44: 0.003677588
A45: 40226 | B45: 1.0458 | C45: 1.0437 | D45: 1.0472 | E45: 1.0411 | F45: 0.0017 | G45: =(C45-C46)/C46 -> -0.0021034516 | H45: =(D45-E45)/E45 -> 0.0058591874 | L45: 0.014 | M45: 0.014 | N45: 187 | P45: =N45/$T$52 -> 0.044249882 | Q45: =P45+Q44 -> 0.94652153 | S45: Sample Variance | T45: 1.3524653e-05
A46: 40227 | B46: 1.0413 | C46: 1.0459 | D46: 1.05 | E46: 1.0397 | F46: -0.0043 | G46: =(C46-C47)/C47 -> 0.0021078854 | H46: =(D46-E46)/E46 -> 0.0099067039 | L46: 0.016 | M46: 0.016 | N46: 103 | P46: =N46/$T$52 -> 0.024372929 | Q46: =P46+Q45 -> 0.97089446 | S46: Kurtosis | T46: 6.8391831
...

Sheet  USDCHF
I1: op to op | J1: average return | K1: =SUBTOTAL(1,G12:G4236) -> 8.444703e-05 | M1: ave pos ret | N1: 0.0042576843 | P1: positive count | Q1: 2042 | R1: =Q1/$T$25 -> 0.48331361 | T1: adj pos ret | U1: =N1*R1 -> 0.0020577968 | W1: std dev | X1: 1 | Y1: 2 | Z1: 3 | AB1: std dev 2 | AC1: actual | AD1: actual % | AE1: normal | AF1: normal%
J2: count | K2: =SUBTOTAL(2,G12:G4236) -> 4225 | M2: ave neg ret | N2: -0.0039124367 | P2: neg count | Q2: 2131 | R2: =Q2/$T$25 -> 0.5043787 | T2: adj neg ret | U2: =N2*R2 -> -0.0019733497 | W2: upper | X2: =T13+(1*T17) -> 0.0063848871 | Y2: =T13+(2*T17) -> 0.012685327 | Z2: =T13+(3*T17) -> 0.018985767 | AB2: 1 | AC2: 3385 | AD2: =AC2/$T$25 -> 0.80118343 | AE2: =AF2*$T$25 -> 2881.45 | AF2: 0.682
P3: 0 count | Q3: =T25-Q1-Q2 -> 52 | R3: =Q3/$T$25 -> 0.012307692 | W3: lower | X3: =T13-(1*T17) -> -0.006215993 | Y3: =T13-(2*T17) -> -0.012516433 | Z3: =T13-(3*T17) -> -0.018816873 | AB3: 2 | AC3: 4090 | AD3: =AC3/$T$25 -> 0.96804734 | AE3: =AF3*$T$25 -> 4030.65 | AF3: 0.954
AB4: 3 | AC4: 4203 | AD4: =AC4/$T$25 -> 0.9947929 | AE4: =AF4*$T$25 -> 4216.55 | AF4: 0.998
A11: Date | B11: Price | C11: Open | D11: High | E11: Low | F11: Change % | G11: OPEN TO OPEN | H11: HIGH TO LOW | L11: INTERVALS | M11: Bin | N11: Frequency | O11: TEXT LABELS | P11: PROBABILITIES | Q11: CUMULATIVE PROBABILITIES | S11: Column1
A12: 40179 | B12: 1.0341 | C12: 1.035 | D12: 1.0353 | E12: 1.0347 | F12: -0.0014 | G12: =(C12-C13)/C13 -> -9.6609023e-05 | H12: =(D12-E12)/E12 -> 0.00057987823 | L12: -0.03 | M12: -0.03 | N12: 2 | O12: =TEXT(L12,"0.00%")&" TO "&TEXT(L13,"0.00%") -> -3.00% TO -2.70% | P12: =N12/$T$25 -> 0.00047337278 | Q12: =P12 -> 0.00047337278
A13: 40182 | B13: 1.0297 | C13: 1.0351 | D13: 1.0423 | E13: 1.0263 | F13: -0.0043 | G13: =(C13-C14)/C14 -> 0.0048538977 | H13: =(D13-E13)/E13 -> 0.015589983 | L13: -0.027 | M13: -0.027 | N13: 1 | O13: =TEXT(L13,"0.00%")&" TO "&TEXT(L14,"0.00%") -> -2.70% TO -2.40% | P13: =N13/$T$25 -> 0.00023668639 | Q13: =P13+Q12 -> 0.00071005917 | S13: Mean | T13: 8.444703e-05
A14: 40183 | B14: 1.0335 | C14: 1.0301 | D14: 1.0364 | E14: 1.0252 | F14: 0.0037 | G14: =(C14-C15)/C15 -> -0.0034826352 | H14: =(D14-E14)/E14 -> 0.010924698 | L14: -0.024 | M14: -0.024 | N14: 1 | O14: =TEXT(L14,"0.00%")&" TO "&TEXT(L15,"0.00%") -> -2.40% TO -2.10% | P14: =N14/$T$25 -> 0.00023668639 | Q14: =P14+Q13 -> 0.00094674556 | S14: Standard Error | T14: 9.6929846e-05
A15: 40184 | B15: 1.0275 | C15: 1.0337 | D15: 1.0383 | E15: 1.0248 | F15: -0.0058 | G15: =(C15-C16)/C16 -> 0.0059361619 | H15: =(D15-E15)/E15 -> 0.013173302 | L15: -0.021 | M15: -0.021 | N15: 1 | O15: =TEXT(L15,"0.00%")&" TO "&TEXT(L16,"0.00%") -> -2.10% TO -1.80% | P15: =N15/$T$25 -> 0.00023668639 | Q15: =P15+Q14 -> 0.001183432 | S15: Median | T15: -0.00010341262
A16: 40185 | B16: 1.0334 | C16: 1.0276 | D16: 1.0374 | E16: 1.0242 | F16: 0.0057 | G16: =(C16-C17)/C17 -> -0.0054200542 | H16: =(D16-E16)/E16 -> 0.012888108 | L16: -0.018 | M16: -0.018 | N16: 4 | O16: =TEXT(L16,"0.00%")&" TO "&TEXT(L17,"0.00%") -> -1.80% TO -1.50% | P16: =N16/$T$25 -> 0.00094674556 | Q16: =P16+Q15 -> 0.0021301775 | S16: Mode | T16: 0
A17: 40186 | B17: 1.0233 | C17: 1.0332 | D17: 1.0388 | E17: 1.0215 | F17: -0.0098 | G17: =(C17-C18)/C18 -> 0.010859994 | H17: =(D17-E17)/E17 -> 0.016935879 | L17: -0.015 | M17: -0.015 | N17: 14 | O17: =TEXT(L17,"0.00%")&" TO "&TEXT(L18,"0.00%") -> -1.50% TO -1.20% | P17: =N17/$T$25 -> 0.0033136095 | Q17: =P17+Q16 -> 0.005443787 | S17: Standard Deviation | T17: 0.00630044
A18: 40189 | B18: 1.0162 | C18: 1.0221 | D18: 1.0246 | E18: 1.013 | F18: -0.0069 | G18: =(C18-C19)/C19 -> 0.006003937 | H18: =(D18-E18)/E18 -> 0.011451135 | L18: -0.012 | M18: -0.012 | N18: 51 | O18: =TEXT(L18,"0.00%")&" TO "&TEXT(L19,"0.00%") -> -1.20% TO -0.90% | P18: =N18/$T$25 -> 0.012071006 | Q18: =P18+Q17 -> 0.017514793 | S18: Sample Variance | T18: 3.9695544e-05
A19: 40190 | B19: 1.0175 | C19: 1.016 | D19: 1.0213 | E19: 1.0143 | F19: 0.0013 | G19: =(C19-C20)/C20 -> -0.0024545901 | H19: =(D19-E19)/E19 -> 0.0069013112 | L19: -0.009 | M19: -0.009 | N19: 114 | O19: =TEXT(L19,"0.00%")&" TO "&TEXT(L20,"0.00%") -> -0.90% TO -0.60% | P19: =N19/$T$25 -> 0.026982249 | Q19: =P19+Q18 -> 0.044497041 | S19: Kurtosis | T19: 195.05521
A20: 40191 | B20: 1.0179 | C20: 1.0185 | D20: 1.0223 | E20: 1.0137 | F20: 0.0004 | G20: =(C20-C21)/C21 -> 0.00039288871 | H20: =(D20-E20)/E20 -> 0.0084837723 | L20: -0.006 | M20: -0.006 | N20: 247 | O20: =TEXT(L20,"0.00%")&" TO "&TEXT(L21,"0.00%") -> -0.60% TO -0.30% | P20: =N20/$T$25 -> 0.058461538 | Q20: =P20+Q19 -> 0.10295858 | S20: Skewness | T20: 5.7704515
A21: 40192 | B21: 1.018 | C21: 1.0181 | D21: 1.0236 | E21: 1.0158 | F21: 0.0001 | G21: =(C21-C22)/C22 -> -0.00039273441 | H21: =(D21-E21)/E21 -> 0.0076786769 | L21: -0.003 | M21: -0.003 | N21: 601 | O21: =TEXT(L21,"0.00%")&" TO "&TEXT(L22,"0.00%") -> -0.30% TO 0.00% | P21: =N21/$T$25 -> 0.14224852 | Q21: =P21+Q20 -> 0.2452071 | S21: Range | T21: 0.27457594
A22: 40193 | B22: 1.0263 | C22: 1.0185 | D22: 1.0292 | E22: 1.0176 | F22: 0.0082 | G22: =(C22-C23)/C23 -> -0.0094339623 | H22: =(D22-E22)/E22 -> 0.011399371 | L22: 0 | M22: 0 | N22: 1147 | O22: =TEXT(L22,"0.00%")&" TO "&TEXT(L23,"0.00%") -> 0.00% TO 0.30% | P22: =N22/$T$25 -> 0.27147929 | Q22: =P22+Q21 -> 0.51668639 | S22: Minimum | T22: -0.08722886
A23: 40196 | B23: 1.0246 | C23: 1.0282 | D23: 1.0296 | E23: 1.0233 | F23: -0.0017 | G23: =(C23-C24)/C24 -> 0.0032198263 | H23: =(D23-E23)/E23 -> 0.0061565523 | L23: 0.003 | M23: 0.003 | N23: 993 | O23: =TEXT(L23,"0.00%")&" TO "&TEXT(L24,"0.00%") -> 0.30% TO 0.60% | P23: =N23/$T$25 -> 0.23502959 | Q23: =P23+Q22 -> 0.75171598 | S23: Maximum | T23: 0.18734708
A24: 40197 | B24: 1.0318 | C24: 1.0249 | D24: 1.036 | E24: 1.0228 | F24: 0.007 | G24: =(C24-C25)/C25 -> -0.0069760682 | H24: =(D24-E24)/E24 -> 0.012905749 | L24: 0.006 | M24: 0.006 | N24: 571 | O24: =TEXT(L24,"0.00%")&" TO "&TEXT(L25,"0.00%") -> 0.60% TO 0.90% | P24: =N24/$T$25 -> 0.13514793 | Q24: =P24+Q23 -> 0.88686391 | S24: Sum | T24: 0.3567887
A25: 40198 | B25: 1.0438 | C25: 1.0321 | D25: 1.0465 | E25: 1.0313 | F25: 0.0116 | G25: =(C25-C26)/C26 -> -0.011587818 | H25: =(D25-E25)/E25 -> 0.014738679 | L25: 0.009 | M25: 0.009 | N25: 289 | O25: =TEXT(L25,"0.00%")&" TO "&TEXT(L26,"0.00%") -> 0.90% TO 1.20% | P25: =N25/$T$25 -> 0.068402367 | Q25: =P25+Q24 -> 0.95526627 | S25: Count | T25: 4225
A26: 40199 | B26: 1.0423 | C26: 1.0442 | D26: 1.0499 | E26: 1.0403 | F26: -0.0014 | G26: =(C26-C27)/C27 -> 0.0016306954 | H26: =(D26-E26)/E26 -> 0.0092281073 | L26: 0.012 | M26: 0.012 | N26: 104 | O26: =TEXT(L26,"0.00%")&" TO "&TEXT(L27,"0.00%") -> 1.20% TO 1.50% | P26: =N26/$T$25 -> 0.024615385 | Q26: =P26+Q25 -> 0.97988166
A27: 40200 | B27: 1.0413 | C27: 1.0425 | D27: 1.0448 | E27: 1.0373 | F27: -0.001 | G27: =(C27-C28)/C28 -> 0.0027895344 | H27: =(D27-E27)/E27 -> 0.0072303095 | L27: 0.015 | M27: 0.015 | N27: 46 | O27: =TEXT(L27,"0.00%")&" TO "&TEXT(L28,"0.00%") -> 1.50% TO 1.80% | P27: =N27/$T$25 -> 0.010887574 | Q27: =P27+Q26 -> 0.99076923
A28: 40203 | B28: 1.0394 | C28: 1.0396 | D28: 1.043 | E28: 1.0365 | F28: -0.0018 | G28: =(C28-C29)/C29 -> -0.00028848928 | H28: =(D28-E28)/E28 -> 0.0062711047 | L28: 0.018 | M28: 0.018 | N28: 20 | O28: =TEXT(L28,"0.00%")&" TO "&TEXT(L29,"0.00%") -> 1.80% TO 2.10% | P28: =N28/$T$25 -> 0.0047337278 | Q28: =P28+Q27 -> 0.99550296
A29: 40204 | B29: 1.0461 | C29: 1.0399 | D29: 1.0495 | E29: 1.0377 | F29: 0.0064 | G29: =(C29-C30)/C30 -> -0.0060217932 | H29: =(D29-E29)/E29 -> 0.011371302 | L29: 0.021 | M29: 0.021 | N29: 7 | O29: =TEXT(L29,"0.00%")&" TO "&TEXT(L30,"0.00%") -> 2.10% TO 2.40% | P29: =N29/$T$25 -> 0.0016568047 | Q29: =P29+Q28 -> 0.99715976
A30: 40205 | B30: 1.0501 | C30: 1.0462 | D30: 1.0528 | E30: 1.0446 | F30: 0.0038 | G30: =(C30-C31)/C31 -> -0.003713932 | H30: =(D30-E30)/E30 -> 0.0078498947 | L30: 0.024 | M30: 0.024 | N30: 2 | O30: =TEXT(L30,"0.00%")&" TO "&TEXT(L31,"0.00%") -> 2.40% TO 2.70% | P30: =N30/$T$25 -> 0.00047337278 | Q30: =P30+Q29 -> 0.99763314
A31: 40206 | B31: 1.0524 | C31: 1.0501 | D31: 1.0558 | E31: 1.0476 | F31: 0.0022 | G31: =(C31-C32)/C32 -> -0.00190096 | H31: =(D31-E31)/E31 -> 0.007827415 | L31: 0.027 | M31: 0.027 | N31: 5 | O31: =TEXT(L31,"0.00%")&" TO "&TEXT(L32,"0.00%") -> 2.70% TO 3.00% | P31: =N31/$T$25 -> 0.001183432 | Q31: =P31+Q30 -> 0.99881657
A32: 40207 | B32: 1.0604 | C32: 1.0521 | D32: 1.0645 | E32: 1.0481 | F32: 0.0076 | G32: =(C32-C33)/C33 -> -0.0080143315 | H32: =(D32-E32)/E32 -> 0.015647362 | L32: 0.03 | M32: 0.03 | N32: 2 | P32: =N32/$T$25 -> 0.00047337278 | Q32: =P32+Q31 -> 0.99928994
A33: 40210 | B33: 1.0556 | C33: 1.0606 | D33: 1.0629 | E33: 1.0551 | F33: -0.0045 | G33: =(C33-C34)/C34 -> 0.0043560606 | H33: =(D33-E33)/E33 -> 0.0073926642 | M33: More | N33: 3 | P33: =N33/$T$25 -> 0.00071005917 | Q33: =P33+Q32 -> 1
A34: 40211 | B34: 1.055 | C34: 1.056 | D34: 1.0612 | E34: 1.054 | F34: -0.0006 | G34: =(C34-C35)/C35 -> 0.0009478673 | H34: =(D34-E34)/E34 -> 0.0068311195
A35: 40212 | B35: 1.059 | C35: 1.055 | D35: 1.0604 | E35: 1.0495 | F35: 0.0038 | G35: =(C35-C36)/C36 -> -0.0038712114 | H35: =(D35-E35)/E35 -> 0.010385898
A36: 40213 | B36: 1.0663 | C36: 1.0591 | D36: 1.0678 | E36: 1.0576 | F36: 0.0069 | G36: =(C36-C37)/C37 -> -0.0065659882 | H36: =(D36-E36)/E36 -> 0.0096444781
A37: 40214 | B37: 1.0731 | C37: 1.0661 | D37: 1.0798 | E37: 1.0644 | F37: 0.0064 | G37: =(C37-C38)/C38 -> -0.006060041 | H37: =(D37-E37)/E37 -> 0.014468245
A38: 40217 | B38: 1.073 | C38: 1.0726 | D38: 1.0777 | E38: 1.0683 | F38: -0.0001 | G38: =(C38-C39)/C39 -> -0.00037278658 | H38: =(D38-E38)/E38 -> 0.0087990265
A39: 40218 | B39: 1.0641 | C39: 1.073 | D39: 1.075 | E39: 1.0607 | F39: -0.0083 | G39: =(C39-C40)/C40 -> 0.0078902874 | H39: =(D39-E39)/E39 -> 0.013481663
A40: 40219 | B40: 1.0681 | C40: 1.0646 | D40: 1.0724 | E40: 1.0617 | F40: 0.0038 | G40: =(C40-C41)/C41 -> -0.0032768467 | H40: =(D40-E40)/E40 -> 0.010078177 | L40: INTERVALS | M40: Bin | N40: Frequency | P40: PROBABILITIES | Q40: CUMULATIVE PROBABILITIES | S40: Column1
A41: 40220 | B41: 1.0706 | C41: 1.0681 | D41: 1.0787 | E41: 1.0625 | F41: 0.0023 | G41: =(C41-C42)/C42 -> -0.0026146232 | H41: =(D41-E41)/E41 -> 0.015247059 | L41: 0.002 | M41: 0.002 | N41: 15 | P41: =N41/$T$54 -> 0.0035494558 | Q41: =P41 -> 0.0035494558
A42: 40221 | B42: 1.0763 | C42: 1.0709 | D42: 1.0834 | E42: 1.0696 | F42: 0.0053 | G42: =(C42-C43)/C43 -> -0.0056638812 | H42: =(D42-E42)/E42 -> 0.012902019 | L42: 0.004 | M42: 0.004 | N42: 313 | P42: =N42/$T$54 -> 0.07406531 | Q42: =P42+Q41 -> 0.077614766 | S42: Mean | T42: 0.0085636089
A43: 40224 | B43: 1.0774 | C43: 1.077 | D43: 1.0809 | E43: 1.0753 | F43: 0.001 | G43: =(C43-C44)/C44 -> -0.00027847396 | H43: =(D43-E43)/E43 -> 0.005207849 | L43: 0.006 | M43: 0.006 | N43: 1025 | P43: =N43/$T$54 -> 0.24254614 | Q43: =P43+Q42 -> 0.32016091 | S43: Standard Error | T43: 0.00011531964
A44: 40225 | B44: 1.0661 | C44: 1.0773 | D44: 1.0793 | E44: 1.0652 | F44: -0.0105 | G44: =(C44-C45)/C45 -> 0.010221305 | H44: =(D44-E44)/E44 -> 0.013236951 | L44: 0.008 | M44: 0.008 | N44: 1044 | P44: =N44/$T$54 -> 0.24704212 | Q44: =P44+Q43 -> 0.56720303 | S44: Median | T44: 0.0074085736
A45: 40226 | B45: 1.0782 | C45: 1.0664 | D45: 1.0802 | E45: 1.0646 | F45: 0.0113 | G45: =(C45-C46)/C46 -> -0.011127596 | H45: =(D45-E45)/E45 -> 0.014653391 | L45: 0.01 | M45: 0.01 | N45: 714 | P45: =N45/$T$54 -> 0.16895409 | Q45: =P45+Q44 -> 0.73615712 | S45: Mode | T45: 0.0073452256
A46: 40227 | B46: 1.0771 | C46: 1.0784 | D46: 1.0831 | E46: 1.0748 | F46: -0.001 | G46: =(C46-C47)/C47 -> -0.0015739283 | H46: =(D46-E46)/E46 -> 0.007722367 | L46: 0.012 | M46: 0.012 | N46: 441 | P46: =N46/$T$54 -> 0.104354 | Q46: =P46+Q45 -> 0.84051112 | S46: Standard Deviation | T46: 0.0074966635
...

Sheet EURJPY
I1: open to open | J1: average ret | K1: =SUBTOTAL(1,G12:G4236) -> -5.1748547e-05 | M1: av post ret | N1: 0.0047941078 | P1: POS COUNT | Q1: 2028 | R1: =Q1/$T$25 -> 0.48 | S1: ADJ POS RET | T1: =N1*R1 -> 0.0023011718 | V1: STD DEV | W1: 1 | X1: 2 | Y1: 3 | AB1: STD DEV 2 | AC1: ACTUAL | AD1: ACTUAL % | AE1: NORMAL | AF1: NORMAL %
J2: counts | K2: =SUBTOTAL(2,G12:G4236) -> 4225 | M2: av neg ret | N2: -0.0045769283 | P2: NEG COUNT | Q2: 2172 | R2: =Q2/$T$25 -> 0.51408284 | S2: ADJ NEG RET | T2: =N2*R2 -> -0.0023529203 | V2: UPPER | W2: =T13+(1*T17) -> 0.0068695668 | X2: =T13+(2*T17) -> 0.013790882 | Y2: =T13+(3*T17) -> 0.020712198 | AB2: 1 | AC2: 3354 | AD2: =AC2/$T$25 -> 0.79384615 | AE2: =AF2*$T$25 -> 2881.45 | AF2: 0.682
P3: 0 COUNT | Q3: =T25-Q1-Q2 -> 25 | R3: =Q3/$T$25 -> 0.0059171598 | V3: LOWER | W3: =T13+(-1*T17) -> -0.0069730639 | X3: =T13+(-2*T17) -> -0.013894379 | Y3: =T13+(-3*T17) -> -0.020815695 | AB3: 2 | AC3: 4043 | AD3: =AC3/$T$25 -> 0.95692308 | AE3: =AF3*$T$25 -> 4030.65 | AF3: 0.954
AB4: 3 | AC4: 4173 | AD4: =AC4/$T$25 -> 0.98769231 | AE4: =AF4*$T$25 -> 4216.55 | AF4: 0.998
A11: Date | B11: Price | C11: Open | D11: High | E11: Low | F11: Change % | G11: OPEN TO OPEN | H11: HIGH TO LOW | L11: INTERVALS | M11: Bin | N11: Frequency | O11: TEXT LABELS | P11: PROBABILITIES | Q11: CUMULATIVE PROBABILITIES | S11: Column1
A12: 40179 | B12: 133.2 | C12: 133.23 | D12: 133.37 | E12: 133.09 | F12: 0.0009 | G12: =(C12-C13)/C13 -> -0.00060010502 | H12: =(D12-E12)/E12 -> 0.0021038395 | L12: -0.03 | M12: -0.03 | N12: 5 | O12: =TEXT(L12,"0.00%")&" TO "&TEXT(L13,"0.00%") -> -3.00% TO -2.70% | P12: =N12/$T$25 -> 0.001183432 | Q12: =P12 -> 0.001183432
A13: 40182 | B13: 133.39 | C13: 133.31 | D13: 133.83 | E13: 132.35 | F13: 0.0014 | G13: =(C13-C14)/C14 -> -0.00037492501 | H13: =(D13-E13)/E13 -> 0.011182471 | L13: -0.027 | M13: -0.027 | N13: 2 | O13: =TEXT(L13,"0.00%")&" TO "&TEXT(L14,"0.00%") -> -2.70% TO -2.40% | P13: =N13/$T$25 -> 0.00047337278 | Q13: =P13+Q12 -> 0.0016568047 | S13: Mean | T13: -5.1748547e-05
A14: 40183 | B14: 131.71 | C14: 133.36 | D14: 133.5 | E14: 131.44 | F14: -0.0126 | G14: =(C14-C15)/C15 -> 0.012373795 | H14: =(D14-E14)/E14 -> 0.01567255 | L14: -0.024 | M14: -0.024 | N14: 5 | O14: =TEXT(L14,"0.00%")&" TO "&TEXT(L15,"0.00%") -> -2.40% TO -2.10% | P14: =N14/$T$25 -> 0.001183432 | Q14: =P14+Q13 -> 0.0028402367 | S14: Standard Error | T14: 0.00010648178
A15: 40184 | B15: 133.05 | C15: 131.73 | D15: 133.54 | E15: 131.24 | F15: 0.0102 | G15: =(C15-C16)/C16 -> -0.010144274 | H15: =(D15-E15)/E15 -> 0.017525145 | L15: -0.021 | M15: -0.021 | N15: 10 | O15: =TEXT(L15,"0.00%")&" TO "&TEXT(L16,"0.00%") -> -2.10% TO -1.80% | P15: =N15/$T$25 -> 0.0023668639 | Q15: =P15+Q14 -> 0.0052071006 | S15: Median | T15: -0.00018894067
A16: 40185 | B16: 133.54 | C16: 133.08 | D16: 133.7 | E16: 132.37 | F16: 0.0037 | G16: =(C16-C17)/C17 -> -0.0033700292 | H16: =(D16-E16)/E16 -> 0.010047594 | L16: -0.018 | M16: -0.018 | N16: 7 | O16: =TEXT(L16,"0.00%")&" TO "&TEXT(L17,"0.00%") -> -1.80% TO -1.50% | P16: =N16/$T$25 -> 0.0016568047 | Q16: =P16+Q15 -> 0.0068639053 | S16: Mode | T16: 0
A17: 40186 | B17: 133.49 | C17: 133.53 | D17: 134.17 | E17: 132.41 | F17: -0.0004 | G17: =(C17-C18)/C18 -> 0.00029964791 | H17: =(D17-E17)/E17 -> 0.013292047 | L17: -0.015 | M17: -0.015 | N17: 40 | O17: =TEXT(L17,"0.00%")&" TO "&TEXT(L18,"0.00%") -> -1.50% TO -1.20% | P17: =N17/$T$25 -> 0.0094674556 | Q17: =P17+Q16 -> 0.016331361 | S17: Standard Deviation | T17: 0.0069213154
A18: 40189 | B18: 133.58 | C18: 133.49 | D18: 134.42 | E18: 133.39 | F18: 0.0007 | G18: =(C18-C19)/C19 -> -0.0016453519 | H18: =(D18-E18)/E18 -> 0.0077217183 | L18: -0.012 | M18: -0.012 | N18: 71 | O18: =TEXT(L18,"0.00%")&" TO "&TEXT(L19,"0.00%") -> -1.20% TO -0.90% | P18: =N18/$T$25 -> 0.016804734 | Q18: =P18+Q17 -> 0.033136095 | S18: Sample Variance | T18: 4.7904607e-05
A19: 40190 | B19: 131.8 | C19: 133.71 | D19: 133.82 | E19: 131.6 | F19: -0.0133 | G19: =(C19-C20)/C20 -> 0.014491654 | H19: =(D19-E19)/E19 -> 0.016869301 | L19: -0.009 | M19: -0.009 | N19: 129 | O19: =TEXT(L19,"0.00%")&" TO "&TEXT(L20,"0.00%") -> -0.90% TO -0.60% | P19: =N19/$T$25 -> 0.030532544 | Q19: =P19+Q18 -> 0.063668639 | S19: Kurtosis | T19: 30.709752
A20: 40191 | B20: 132.6 | C20: 131.8 | D20: 133.24 | E20: 131.5 | F20: 0.0061 | G20: =(C20-C21)/C21 -> -0.0066324992 | H20: =(D20-E20)/E20 -> 0.013231939 | L20: -0.006 | M20: -0.006 | N20: 287 | O20: =TEXT(L20,"0.00%")&" TO "&TEXT(L21,"0.00%") -> -0.60% TO -0.30% | P20: =N20/$T$25 -> 0.067928994 | Q20: =P20+Q19 -> 0.13159763 | S20: Skewness | T20: 0.33068683
A21: 40192 | B21: 132.21 | C21: 132.68 | D21: 133.67 | E21: 131.69 | F21: -0.0029 | G21: =(C21-C22)/C22 -> 0.0038586669 | H21: =(D21-E21)/E21 -> 0.01503531 | L21: -0.003 | M21: -0.003 | N21: 627 | O21: =TEXT(L21,"0.00%")&" TO "&TEXT(L22,"0.00%") -> -0.30% TO 0.00% | P21: =N21/$T$25 -> 0.14840237 | Q21: =P21+Q20 -> 0.28 | S21: Range | T21: 0.21064123
A22: 40193 | B22: 130.58 | C22: 132.17 | D22: 132.43 | E22: 130.28 | F22: -0.0123 | G22: =(C22-C23)/C23 -> 0.01442935 | H22: =(D22-E22)/E22 -> 0.016502917 | L22: 0 | M22: 0 | N22: 1014 | O22: =TEXT(L22,"0.00%")&" TO "&TEXT(L23,"0.00%") -> 0.00% TO 0.30% | P22: =N22/$T$25 -> 0.24 | Q22: =P22+Q21 -> 0.52 | S22: Minimum | T22: -0.1076523
A23: 40196 | B23: 130.55 | C23: 130.29 | D23: 130.99 | E23: 130.07 | F23: -0.0002 | G23: =(C23-C24)/C24 -> -0.0018386578 | H23: =(D23-E23)/E23 -> 0.0070731145 | L23: 0.003 | M23: 0.003 | N23: 925 | O23: =TEXT(L23,"0.00%")&" TO "&TEXT(L24,"0.00%") -> 0.30% TO 0.60% | P23: =N23/$T$25 -> 0.21893491 | Q23: =P23+Q22 -> 0.73893491 | S23: Maximum | T23: 0.10298893
A24: 40197 | B24: 130.24 | C24: 130.53 | D24: 130.76 | E24: 129.6 | F24: -0.0024 | G24: =(C24-C25)/C25 -> 0.0017651573 | H24: =(D24-E24)/E24 -> 0.0089506173 | L24: 0.006 | M24: 0.006 | N24: 571 | O24: =TEXT(L24,"0.00%")&" TO "&TEXT(L25,"0.00%") -> 0.60% TO 0.90% | P24: =N24/$T$25 -> 0.13514793 | Q24: =P24+Q23 -> 0.87408284 | S24: Sum | T24: -0.21863761
A25: 40198 | B25: 128.64 | C25: 130.3 | D25: 130.39 | E25: 128.39 | F25: -0.0123 | G25: =(C25-C26)/C26 -> 0.012746774 | H25: =(D25-E25)/E25 -> 0.015577537 | L25: 0.009 | M25: 0.009 | N25: 251 | O25: =TEXT(L25,"0.00%")&" TO "&TEXT(L26,"0.00%") -> 0.90% TO 1.20% | P25: =N25/$T$25 -> 0.059408284 | Q25: =P25+Q24 -> 0.93349112 | S25: Count | T25: 4225
A26: 40199 | B26: 127.4 | C26: 128.66 | D26: 129.55 | E26: 127.02 | F26: -0.0096 | G26: =(C26-C27)/C27 -> 0.0095731325 | H26: =(D26-E26)/E26 -> 0.019918123 | L26: 0.012 | M26: 0.012 | N26: 136 | O26: =TEXT(L26,"0.00%")&" TO "&TEXT(L27,"0.00%") -> 1.20% TO 1.50% | P26: =N26/$T$25 -> 0.032189349 | Q26: =P26+Q25 -> 0.96568047
A27: 40200 | B27: 127.06 | C27: 127.44 | D27: 128.22 | E27: 126.55 | F27: -0.0027 | G27: =(C27-C28)/C28 -> -0.0035965598 | H27: =(D27-E27)/E27 -> 0.013196365 | L27: 0.015 | M27: 0.015 | N27: 72 | O27: =TEXT(L27,"0.00%")&" TO "&TEXT(L28,"0.00%") -> 1.50% TO 1.80% | P27: =N27/$T$25 -> 0.01704142 | Q27: =P27+Q26 -> 0.98272189
A28: 40203 | B28: 127.67 | C28: 127.9 | D28: 128.17 | E28: 127.05 | F28: 0.0048 | G28: =(C28-C29)/C29 -> 0.0014093329 | H28: =(D28-E28)/E28 -> 0.008815427 | L28: 0.018 | M28: 0.018 | N28: 28 | O28: =TEXT(L28,"0.00%")&" TO "&TEXT(L29,"0.00%") -> 1.80% TO 2.10% | P28: =N28/$T$25 -> 0.0066272189 | Q28: =P28+Q27 -> 0.98934911
A29: 40204 | B29: 126.15 | C29: 127.72 | D29: 128.4 | E29: 125.66 | F29: -0.0119 | G29: =(C29-C30)/C30 -> 0.012044374 | H29: =(D29-E29)/E29 -> 0.02180487 | L29: 0.021 | M29: 0.021 | N29: 20 | O29: =TEXT(L29,"0.00%")&" TO "&TEXT(L30,"0.00%") -> 2.10% TO 2.40% | P29: =N29/$T$25 -> 0.0047337278 | Q29: =P29+Q28 -> 0.99408284
A30: 40205 | B30: 126.19 | C30: 126.2 | D30: 126.45 | E30: 125.21 | F30: 0.0003 | G30: =(C30-C31)/C31 -> 0.00015850372 | H30: =(D30-E30)/E30 -> 0.0099033624 | L30: 0.024 | M30: 0.024 | N30: 10 | O30: =TEXT(L30,"0.00%")&" TO "&TEXT(L31,"0.00%") -> 2.40% TO 2.70% | P30: =N30/$T$25 -> 0.0023668639 | Q30: =P30+Q29 -> 0.9964497
A31: 40206 | B31: 125.5 | C31: 126.18 | D31: 127.1 | E31: 125.08 | F31: -0.0055 | G31: =(C31-C32)/C32 -> 0.0049378783 | H31: =(D31-E31)/E31 -> 0.016149664 | L31: 0.027 | M31: 0.027 | N31: 5 | O31: =TEXT(L31,"0.00%")&" TO "&TEXT(L32,"0.00%") -> 2.70% TO 3.00% | P31: =N31/$T$25 -> 0.001183432 | Q31: =P31+Q30 -> 0.99763314
A32: 40207 | B32: 125.13 | C32: 125.56 | D32: 126.73 | E32: 124.78 | F32: -0.0029 | G32: =(C32-C33)/C33 -> 0.0074620878 | H32: =(D32-E32)/E32 -> 0.015627504 | L32: 0.03 | M32: 0.03 | N32: 3 | O32: =TEXT(L32,"0.00%")&" TO "&TEXT(L33,"0.00%") -> 3.00% TO 0.00% | P32: =N32/$T$25 -> 0.00071005917 | Q32: =P32+Q31 -> 0.9983432
A33: 40210 | B33: 126.22 | C33: 124.63 | D33: 126.54 | E33: 124.48 | F33: 0.0087 | G33: =(C33-C34)/C34 -> -0.012831683 | H33: =(D33-E33)/E33 -> 0.016548843 | M33: More | N33: 7 | O33: =TEXT(L33,"0.00%")&" TO "&TEXT(L34,"0.00%") -> 0.00% TO 0.00% | P33: =N33/$T$25 -> 0.0016568047 | Q33: =P33+Q32 -> 1
A34: 40211 | B34: 126.14 | C34: 126.25 | D34: 126.72 | E34: 125.79 | F34: -0.0006 | G34: =(C34-C35)/C35 -> 0.00039619651 | H34: =(D34-E34)/E34 -> 0.0073932745
A35: 40212 | B35: 126.44 | C35: 126.2 | D35: 127 | E35: 125.95 | F35: 0.0024 | G35: =(C35-C36)/C36 -> -0.001740231 | H35: =(D35-E35)/E35 -> 0.0083366415
A36: 40213 | B36: 122.18 | C36: 126.42 | D36: 126.5 | E36: 121.58 | F36: -0.0337 | G36: =(C36-C37)/C37 -> 0.034448899 | H36: =(D36-E36)/E36 -> 0.040467182
A37: 40214 | B37: 122.05 | C37: 122.21 | D37: 123.34 | E37: 120.68 | F37: -0.0011 | G37: =(C37-C38)/C38 -> -0.0018784711 | H37: =(D37-E37)/E37 -> 0.022041763 | L37: INTERVALS | M37: Bin | N37: Frequency | P37: PROBABILITIES | Q37: CUMULATIVE PROBABILITIES | S37: Column1
A38: 40217 | B38: 121.92 | C38: 122.44 | D38: 122.81 | E38: 121.54 | F38: -0.0011 | G38: =(C38-C39)/C39 -> 0.0040180402 | H38: =(D38-E38)/E38 -> 0.010449235 | L38: 0.002 | M38: 0.002 | N38: 4 | P38: =N38/$T$51 -> 0.00094674556 | Q38: =P38 -> 0.00094674556
A39: 40218 | B39: 123.57 | C39: 121.95 | D39: 124.2 | E39: 121.63 | F39: 0.0135 | G39: =(C39-C40)/C40 -> -0.013109978 | H39: =(D39-E39)/E39 -> 0.021129656 | L39: 0.004 | M39: 0.004 | N39: 216 | P39: =N39/$T$51 -> 0.05112426 | Q39: =P39+Q38 -> 0.052071006 | S39: Mean | T39: 0.0099388198
A40: 40219 | B40: 123.48 | C40: 123.57 | D40: 124.31 | E40: 122.67 | F40: -0.0007 | G40: =(C40-C41)/C41 -> 0.00056680162 | H40: =(D40-E40)/E40 -> 0.013369202 | L40: 0.006 | M40: 0.006 | N40: 774 | P40: =N40/$T$51 -> 0.18319527 | Q40: =P40+Q39 -> 0.23526627 | S40: Standard Error | T40: 0.00022222353
A41: 40220 | B41: 122.75 | C41: 123.5 | D41: 124.19 | E41: 122.04 | F41: -0.0059 | G41: =(C41-C42)/C42 -> 0.0054546935 | H41: =(D41-E41)/E41 -> 0.017617175 | L41: 0.008 | M41: 0.008 | N41: 958 | P41: =N41/$T$51 -> 0.22674556 | Q41: =P41+Q40 -> 0.46201183 | S41: Median | T41: 0.008387698
A42: 40221 | B42: 122.58 | C42: 122.83 | D42: 123.12 | E42: 121.36 | F42: -0.0014 | G42: =(C42-C43)/C43 -> 0.0015492498 | H42: =(D42-E42)/E42 -> 0.014502307 | L42: 0.01 | M42: 0.01 | N42: 730 | P42: =N42/$T$51 -> 0.17278107 | Q42: =P42+Q41 -> 0.6347929 | S42: Mode | T42: 0.010329402
A43: 40224 | B43: 122.35 | C43: 122.64 | D43: 122.91 | E43: 122.22 | F43: -0.0019 | G43: =(C43-C44)/C44 -> 0.0020426505 | H43: =(D43-E43)/E43 -> 0.0056455572 | L43: 0.012 | M43: 0.012 | N43: 523 | P43: =N43/$T$51 -> 0.12378698 | Q43: =P43+Q42 -> 0.75857988 | S43: Standard Deviation | T43: 0.01444453
A44: 40225 | B44: 124.04 | C44: 122.39 | D44: 124.51 | E44: 122.29 | F44: 0.0138 | G44: =(C44-C45)/C45 -> -0.014017562 | H44: =(D44-E44)/E44 -> 0.018153569 | L44: 0.014 | M44: 0.014 | N44: 361 | P44: =N44/$T$51 -> 0.085443787 | Q44: =P44+Q43 -> 0.84402367 | S44: Sample Variance | T44: 0.00020864444
A45: 40226 | B45: 124.24 | C45: 124.13 | D45: 124.89 | E45: 123.39 | F45: 0.0016 | G45: =(C45-C46)/C46 -> 0 | H45: =(D45-E45)/E45 -> 0.012156577 | L45: 0.016 | M45: 0.016 | N45: 221 | P45: =N45/$T$51 -> 0.052307692 | Q45: =P45+Q44 -> 0.89633136 | S45: Kurtosis | T45: 3003.1346
A46: 40227 | B46: 124.19 | C46: 124.13 | D46: 124.49 | E46: 122.73 | F46: -0.0004 | G46: =(C46-C47)/C47 -> -0.00056360709 | H46: =(D46-E46)/E46 -> 0.014340422 | L46: 0.018 | M46: 0.018 | N46: 156 | P46: =N46/$T$51 -> 0.036923077 | Q46: =P46+Q45 -> 0.93325444 | S46: Skewness | T46: 50.548819
...

Sheet USDZAR
I1: open to open | J1: average ret | K1: =SUBTOTAL(1,G12:G4236) -> 0.00023743745 | M1: av post ret | N1: 0.0075166863 | P1: POS COUNT | Q1: 2064 | R1: =Q1/$R$25 -> 0.48852071 | S1: ADJ AV POST RET | T1: =N1*R1 -> 0.0036720569 | V1: STD DEV | W1: 1 | X1: 2 | Y1: 3 | AB1: STD DEV 2 | AC1: ACTUAL | AD1: ACTUAL% | AE1: NORMAL | AF1: NORMAL %
J2: count | K2: =SUBTOTAL(2,G15:G4236) -> 4222 | M2: av neg ret | N2: -0.0067379774 | P2: NEG COUNT | Q2: 2157 | R2: =Q2/$R$25 -> 0.51053254 | S2: ADJ AV NEG RET | T2: =N2*R2 -> -0.0034399568 | V2: UPPER | W2: =R13+(1*R17) -> 0.0095252432 | X2: =R13+(2*R17) -> 0.018813049 | Y2: =R13+(3*R17) -> 0.028100855 | AB2: 1 | AC2: 3050 | AD2: =AC2/$R$25 -> 0.72189349 | AE2: =AF2*$R$25 -> 2881.45 | AF2: 0.682
P3: 0 COUNT | Q3: =R25-Q1-Q2 -> 4 | R3: =Q3/$R$25 -> 0.00094674556 | V3: LOWER | W3: =R13+(-1*R17) -> -0.0090503683 | X3: =R13+(-2*R17) -> -0.018338174 | Y3: =R13+(-3*R17) -> -0.02762598 | AB3: 2 | AC3: 4006 | AD3: =AC3/$R$25 -> 0.94816568 | AE3: =AF3*$R$25 -> 4030.65 | AF3: 0.954
AB4: 3 | AC4: 4183 | AD4: =AC4/$R$25 -> 0.99005917 | AE4: =AF4*$R$25 -> 4216.55 | AF4: 0.998
A11: Date | B11: Price | C11: Open | D11: High | E11: Low | F11: Change % | G11: OPEN TO OPEN | H11: HIGH TO LOW | J11: INTER | K11: Bin | L11: Frequency | M11: TEXT LABELS | N11: PROBABILITIES | O11: CUMULATIVE PROBABILITIES | Q11: Column1
A12: 46094 | B12: 16.9553 | C12: 16.8001 | D12: 16.9738 | E12: 16.7163 | F12: 0.0093 | G12: =(C12-C13)/C13 -> 0.018867124 | H12: =(D12-E12)/E12 -> 0.015404127 | J12: -0.03 | K12: -0.03 | L12: 4 | M12: =TEXT(J12,"0.00%")&" TO "&TEXT(J13,"0.00%") -> -3.00% TO -2.70% | N12: =L12/$R$25 -> 0.00094674556 | O12: =N12 -> 0.00094674556
A13: 46093 | B13: 16.7999 | C13: 16.489 | D13: 16.8103 | E13: 16.4388 | F13: 0.0189 | G13: =(C13-C14)/C14 -> 0.012073188 | H13: =(D13-E13)/E13 -> 0.022598973 | J13: -0.027 | K13: -0.027 | L13: 6 | M13: =TEXT(J13,"0.00%")&" TO "&TEXT(J14,"0.00%") -> -2.70% TO -2.40% | N13: =L13/$R$25 -> 0.0014201183 | O13: =N13+O12 -> 0.0023668639 | Q13: Mean | R13: 0.00023743745
A14: 46092 | B14: 16.489 | C14: 16.2923 | D14: 16.5258 | E14: 16.2035 | F14: 0.0119 | G14: =(C14-C15)/C15 -> 0.00027628041 | H14: =(D14-E14)/E14 -> 0.019890764 | J14: -0.024 | K14: -0.024 | L14: 16 | M14: =TEXT(J14,"0.00%")&" TO "&TEXT(J15,"0.00%") -> -2.40% TO -2.10% | N14: =L14/$R$25 -> 0.0037869822 | O14: =N14+O13 -> 0.0061538462 | Q14: Standard Error | R14: 0.00014288932
A15: 46091 | B15: 16.2955 | C15: 16.2878 | D15: 16.3943 | E15: 16.1263 | F15: 0.0004 | G15: =(C15-C16)/C16 -> -0.02542378 | H15: =(D15-E15)/E15 -> 0.016618815 | J15: -0.021 | K15: -0.021 | L15: 20 | M15: =TEXT(J15,"0.00%")&" TO "&TEXT(J16,"0.00%") -> -2.10% TO -1.80% | N15: =L15/$R$25 -> 0.0047337278 | O15: =N15+O14 -> 0.010887574 | Q15: Median | R15: -0.00019139075
A16: 46090 | B16: 16.2892 | C16: 16.7127 | D16: 16.9203 | E16: 16.27 | F16: -0.0163 | G16: =(C16-C17)/C17 -> 0.0035969927 | H16: =(D16-E16)/E16 -> 0.039969269 | J16: -0.018 | K16: -0.018 | L16: 38 | M16: =TEXT(J16,"0.00%")&" TO "&TEXT(J17,"0.00%") -> -1.80% TO -1.50% | N16: =L16/$R$25 -> 0.0089940828 | O16: =N16+O15 -> 0.019881657 | Q16: Mode | R16: -0.0072162087
A17: 46087 | B17: 16.5588 | C17: 16.6528 | D17: 16.8215 | E17: 16.5228 | F17: -0.0057 | G17: =(C17-C18)/C18 -> 0.019062131 | H17: =(D17-E17)/E17 -> 0.01807805 | J17: -0.015 | K17: -0.015 | L17: 76 | M17: =TEXT(J17,"0.00%")&" TO "&TEXT(J18,"0.00%") -> -1.50% TO -1.20% | N17: =L17/$R$25 -> 0.017988166 | O17: =N17+O16 -> 0.037869822 | Q17: Standard Deviation | R17: 0.0092878057
A18: 46086 | B18: 16.653 | C18: 16.3413 | D18: 16.749 | E18: 16.3117 | F18: 0.0191 | G18: =(C18-C19)/C19 -> -0.011188295 | H18: =(D18-E18)/E18 -> 0.026808978 | J18: -0.012 | K18: -0.012 | L18: 154 | M18: =TEXT(J18,"0.00%")&" TO "&TEXT(J19,"0.00%") -> -1.20% TO -0.90% | N18: =L18/$R$25 -> 0.036449704 | O18: =N18+O17 -> 0.074319527 | Q18: Sample Variance | R18: 8.6263335e-05
A19: 46085 | B19: 16.3413 | C19: 16.5262 | D19: 16.635 | E19: 16.2841 | F19: -0.0114 | G19: =(C19-C20)/C20 -> 0.025115841 | H19: =(D19-E19)/E19 -> 0.021548627 | J19: -0.009 | K19: -0.009 | L19: 260 | M19: =TEXT(J19,"0.00%")&" TO "&TEXT(J20,"0.00%") -> -0.90% TO -0.60% | N19: =L19/$R$25 -> 0.061538462 | O19: =N19+O18 -> 0.13585799 | Q19: Kurtosis | R19: 1.669684
A20: 46084 | B20: 16.5305 | C20: 16.1213 | D20: 16.7594 | E20: 16.0516 | F20: 0.0267 | G20: =(C20-C21)/C21 -> 0.011596022 | H20: =(D20-E20)/E20 -> 0.044095293 | J20: -0.006 | K20: -0.006 | L20: 434 | M20: =TEXT(J20,"0.00%")&" TO "&TEXT(J21,"0.00%") -> -0.60% TO -0.30% | N20: =L20/$R$25 -> 0.10272189 | O20: =N20+O19 -> 0.23857988 | Q20: Skewness | R20: 0.42250534
A21: 46083 | B21: 16.0999 | C21: 15.9365 | D21: 16.2133 | E21: 15.9365 | F21: 0.0103 | G21: =(C21-C22)/C22 -> 0.00013806694 | H21: =(D21-E21)/E21 -> 0.017368933 | J21: -0.003 | K21: -0.003 | L21: 552 | M21: =TEXT(J21,"0.00%")&" TO "&TEXT(J22,"0.00%") -> -0.30% TO 0.00% | N21: =L21/$R$25 -> 0.13065089 | O21: =N21+O20 -> 0.36923077 | Q21: Range | R21: 0.10601225
A22: 46080 | B22: 15.9365 | C22: 15.9343 | D22: 16.005 | E22: 15.8678 | F22: -0.0003 | G22: =(C22-C23)/C23 -> 0.0057310569 | H22: =(D22-E22)/E22 -> 0.0086464412 | J22: 0 | K22: 0 | L22: 598 | M22: =TEXT(J22,"0.00%")&" TO "&TEXT(J23,"0.00%") -> 0.00% TO 0.30% | N22: =L22/$R$25 -> 0.14153846 | O22: =N22+O21 -> 0.51076923 | Q22: Minimum | R22: -0.03843821
A23: 46079 | B23: 15.9408 | C23: 15.8435 | D23: 16.008 | E23: 15.8316 | F23: 0.0059 | G23: =(C23-C24)/C24 -> -0.0072994987 | H23: =(D23-E23)/E23 -> 0.011142272 | J23: 0.003 | K23: 0.003 | L23: 571 | M23: =TEXT(J23,"0.00%")&" TO "&TEXT(J24,"0.00%") -> 0.30% TO 0.60% | N23: =L23/$R$25 -> 0.13514793 | O23: =N23+O22 -> 0.64591716 | Q23: Maximum | R23: 0.067574043
A24: 46078 | B24: 15.8475 | C24: 15.96 | D24: 15.991 | E24: 15.8292 | F24: -0.008 | G24: =(C24-C25)/C25 -> -0.0021133189 | H24: =(D24-E24)/E24 -> 0.010221616 | J24: 0.006 | K24: 0.006 | L24: 477 | M24: =TEXT(J24,"0.00%")&" TO "&TEXT(J25,"0.00%") -> 0.60% TO 0.90% | N24: =L24/$R$25 -> 0.11289941 | O24: =N24+O23 -> 0.75881657 | Q24: Sum | R24: 1.0031732
A25: 46077 | B25: 15.976 | C25: 15.9938 | D25: 16.054 | E25: 15.9274 | F25: -0.0029 | G25: =(C25-C26)/C26 -> -0.0038429199 | H25: =(D25-E25)/E25 -> 0.0079485666 | J25: 0.009 | K25: 0.009 | L25: 363 | M25: =TEXT(J25,"0.00%")&" TO "&TEXT(J26,"0.00%") -> 0.90% TO 1.20% | N25: =L25/$R$25 -> 0.08591716 | O25: =N25+O24 -> 0.84473373 | Q25: Count | R25: 4225
A26: 46076 | B26: 16.0223 | C26: 16.0555 | D26: 16.0709 | E26: 15.9483 | F26: -0.0011 | G26: =(C26-C27)/C27 -> -0.0055681494 | H26: =(D26-E26)/E26 -> 0.0076873397 | J26: 0.012 | K26: 0.012 | L26: 253 | M26: =TEXT(J26,"0.00%")&" TO "&TEXT(J27,"0.00%") -> 1.20% TO 1.50% | N26: =L26/$R$25 -> 0.059881657 | O26: =N26+O25 -> 0.90461538
A27: 46073 | B27: 16.0397 | C27: 16.1454 | D27: 16.1994 | E27: 15.9823 | F27: -0.0065 | G27: =(C27-C28)/C28 -> 0.0042232934 | H27: =(D27-E27)/E27 -> 0.013583777 | J27: 0.015 | K27: 0.015 | L27: 160 | M27: =TEXT(J27,"0.00%")&" TO "&TEXT(J28,"0.00%") -> 1.50% TO 1.80% | N27: =L27/$R$25 -> 0.037869822 | O27: =N27+O26 -> 0.94248521
A28: 46072 | B28: 16.1453 | C28: 16.0775 | D28: 16.2285 | E28: 16.023 | F28: 0.0049 | G28: =(C28-C29)/C29 -> 0.0027192386 | H28: =(D28-E28)/E28 -> 0.012825314 | J28: 0.018 | K28: 0.018 | L28: 94 | M28: =TEXT(J28,"0.00%")&" TO "&TEXT(J29,"0.00%") -> 1.80% TO 2.10% | N28: =L28/$R$25 -> 0.022248521 | O28: =N28+O27 -> 0.96473373
A29: 46071 | B29: 16.0669 | C29: 16.0339 | D29: 16.1086 | E29: 15.95 | F29: 0.0021 | G29: =(C29-C30)/C30 -> 0.0041584468 | H29: =(D29-E29)/E29 -> 0.0099435737 | J29: 0.021 | K29: 0.021 | L29: 54 | M29: =TEXT(J29,"0.00%")&" TO "&TEXT(J30,"0.00%") -> 2.10% TO 2.40% | N29: =L29/$R$25 -> 0.012781065 | O29: =N29+O28 -> 0.97751479
A30: 46070 | B30: 16.0339 | C30: 15.9675 | D30: 16.1167 | E30: 15.94 | F30: 0.0033 | G30: =(C30-C31)/C31 -> 0.0011034552 | H30: =(D30-E30)/E30 -> 0.01108532 | J30: 0.024 | K30: 0.024 | L30: 44 | M30: =TEXT(J30,"0.00%")&" TO "&TEXT(J31,"0.00%") -> 2.40% TO 2.70% | N30: =L30/$R$25 -> 0.010414201 | O30: =N30+O29 -> 0.98792899
A31: 46069 | B31: 15.9816 | C31: 15.9499 | D31: 16.0006 | E31: 15.879 | F31: 0.0023 | G31: =(C31-C32)/C32 -> 0.00093504864 | H31: =(D31-E31)/E31 -> 0.007657913 | J31: 0.027 | K31: 0.027 | L31: 18 | M31: =TEXT(J31,"0.00%")&" TO "&TEXT(J32,"0.00%") -> 2.70% TO 3.00% | N31: =L31/$R$25 -> 0.004260355 | O31: =N31+O30 -> 0.99218935
A32: 46066 | B32: 15.9456 | C32: 15.935 | D32: 16.0798 | E32: 15.9305 | F32: -0.0009 | G32: =(C32-C33)/C33 -> 0.0034634761 | H32: =(D32-E32)/E32 -> 0.0093719594 | J32: 0.03 | K32: 0.03 | L32: 13 | N32: =L32/$R$25 -> 0.0030769231 | O32: =N32+O31 -> 0.99526627
A33: 46065 | B33: 15.9601 | C33: 15.88 | D33: 15.9932 | E33: 15.8045 | F33: 0.006 | G33: =(C33-C34)/C34 -> -0.0035703305 | H33: =(D33-E33)/E33 -> 0.011939637 | K33: More | L33: 20 | N33: =L33/$R$25 -> 0.0047337278 | O33: =N33+O32 -> 1
A34: 46064 | B34: 15.8653 | C34: 15.9369 | D34: 15.96 | E34: 15.8336 | F34: -0.0046 | G34: =(C34-C35)/C35 -> 0.0024279325 | H34: =(D34-E34)/E34 -> 0.0079830234
A35: 46063 | B35: 15.9382 | C35: 15.8983 | D35: 15.9798 | E35: 15.8783 | F35: 0.0025 | G35: =(C35-C36)/C36 -> -0.0093282652 | H35: =(D35-E35)/E35 -> 0.006392372
A36: 46062 | B36: 15.8983 | C36: 16.048 | D36: 16.0787 | E36: 15.8694 | F36: -0.0089 | G36: =(C36-C37)/C37 -> -0.016202498 | H36: =(D36-E36)/E36 -> 0.013188904
A37: 46059 | B37: 16.0414 | C37: 16.3123 | D37: 16.4338 | E37: 15.9966 | F37: -0.0166 | G37: =(C37-C38)/C38 -> 0.014667372 | H37: =(D37-E37)/E37 -> 0.027330808 | J37: INTERVALS | K37: Bin | L37: Frequency | N37: PROBABILITIES | O37: CUMULATIVE PROBABILITIES | P37: Column1
A38: 46058 | B38: 16.3129 | C38: 16.0765 | D38: 16.3197 | E38: 16.0495 | F38: 0.0144 | G38: =(C38-C39)/C39 -> 0.0061143515 | H38: =(D38-E38)/E38 -> 0.016835415 | J38: 0.002 | K38: 0.002 | L38: 4 | N38: =L38/$Q$51 -> 0.00094652153 | O38: =N38 -> 0.00094652153
A39: 46057 | B39: 16.0814 | C39: 15.9788 | D39: 16.1446 | E39: 15.9033 | F39: 0.0068 | G39: =(C39-C40)/C40 -> -0.0067567988 | H39: =(D39-E39)/E39 -> 0.015172952 | J39: 0.004 | K39: 0.004 | L39: 10 | N39: =L39/$Q$51 -> 0.0023663038 | O39: =N39+O38 -> 0.0033128254 | P39: Mean | Q39: 0.016457921
A40: 46056 | B40: 15.9733 | C40: 16.0875 | D40: 16.114 | E40: 15.9064 | F40: -0.0071 | G40: =(C40-C41)/C41 -> -0.0027832189 | H40: =(D40-E40)/E40 -> 0.01305135 | J40: 0.006 | K40: 0.006 | L40: 49 | N40: =L40/$Q$51 -> 0.011594889 | O40: =N40+O39 -> 0.014907714 | P40: Standard Error | Q40: 0.0001160701
A41: 46055 | B41: 16.0869 | C41: 16.1324 | D41: 16.3162 | E41: 15.9567 | F41: -0.0032 | G41: =(C41-C42)/C42 -> 0.025079904 | H41: =(D41-E41)/E41 -> 0.022529721 | J41: 0.008 | K41: 0.008 | L41: 205 | N41: =L41/$Q$51 -> 0.048509229 | O41: =N41+O40 -> 0.063416943 | P41: Median | Q41: 0.015164088
A42: 46052 | B42: 16.1384 | C42: 15.7377 | D42: 16.2113 | E42: 15.7221 | F42: 0.0256 | G42: =(C42-C43)/C43 -> -0.0021114704 | H42: =(D42-E42)/E42 -> 0.031115436 | J42: 0.01 | K42: 0.01 | L42: 419 | N42: =L42/$Q$51 -> 0.099148131 | O42: =N42+O41 -> 0.16256507 | P42: Mode | Q42: 0
A43: 46051 | B43: 15.7354 | C43: 15.771 | D43: 15.935 | E43: 15.6417 | F43: -0.0023 | G43: =(C43-C44)/C44 -> -0.0058372627 | H43: =(D43-E43)/E43 -> 0.018751159 | J43: 0.012 | K43: 0.012 | L43: 517 | N43: =L43/$Q$51 -> 0.12233791 | O43: =N43+O42 -> 0.28490298 | P43: Standard Deviation | Q43: 0.0075454492
A44: 46050 | B44: 15.7713 | C44: 15.8636 | D44: 15.9799 | E44: 15.7591 | F44: -0.0058 | G44: =(C44-C45)/C45 -> -0.0086055508 | H44: =(D44-E44)/E44 -> 0.014010952 | J44: 0.014 | K44: 0.014 | L44: 569 | N44: =L44/$Q$51 -> 0.13464269 | O44: =N44+O43 -> 0.41954567 | P44: Sample Variance | Q44: 5.6933804e-05
